<?xml version="1.0"?>
<sdf version='1.7'>
  <model name='robozinho'>
    <link name='base_footprint'>
      <inertial>
        <pose>0 0 0.0218 0 -0 0</pose>
        <mass>2.4</mass>
        <inertia>
          <ixx>0.019995</ixx>
          <ixy>-6.77626e-21</ixy>
          <ixz>0</ixz>
          <iyy>0.019995</iyy>
          <iyz>0</iyz>
          <izz>0.03675</izz>
        </inertia>
      </inertial>
      <collision name='base_footprint_fixed_joint_lump__base_link_collision'>
        <pose>0 0 0.0218 0 -0 3.14</pose>
        <geometry>
          <mesh>
            <scale>1 1 1</scale>
            <uri>model://meshes/ELV_conjuntocompleto.dae</uri>
          </mesh>
        </geometry>
      </collision>
      <visual name='base_footprint_fixed_joint_lump__base_link_visual'>
        <pose>0 0 0.0218 0 -0 3.14</pose>
        <geometry>
          <mesh>
            <scale>1 1 1</scale>
            <uri>model://meshes/ELV_conjuntocompleto.dae</uri>
          </mesh>
        </geometry>
      </visual>
    </link>
    <joint name='wheel_left_joint' type='revolute'>
      <pose relative_to='base_footprint'>-0.214 0 0.0607 0 1.57 0</pose>
      <parent>base_footprint</parent>
      <child>wheel_left_link</child>
      <axis>
        <xyz>0 0 1</xyz>
        <limit>
          <lower>-1e+16</lower>
          <upper>1e+16</upper>
        </limit>
        <dynamics>
          <spring_reference>0</spring_reference>
          <spring_stiffness>0</spring_stiffness>
        </dynamics>
      </axis>
    </joint>
    <link name='wheel_left_link'>
      <pose relative_to='wheel_left_joint'>0 0 0 0 -0 0</pose>
      <inertial>
        <pose>0 0 0 0 -0 0</pose>
        <mass>1</mass>
        <inertia>
          <ixx>0.001</ixx>
          <ixy>0</ixy>
          <ixz>0</ixz>
          <iyy>0.001</iyy>
          <iyz>0</iyz>
          <izz>0.001</izz>
        </inertia>
      </inertial>
      <collision name='wheel_left_link_collision'>
        <pose>0 0 0 0 -0 0</pose>
        <geometry>
          <mesh>
            <scale>1 1 1</scale>
            <uri>model://meshes/M_rodatrativa.dae</uri>
          </mesh>
        </geometry>
      </collision>
      <visual name='wheel_left_link_visual'>
        <pose>0 0 0 0 -0 0</pose>
        <geometry>
          <mesh>
            <scale>1 1 1</scale>
            <uri>model://meshes/M_rodatrativa.dae</uri>
          </mesh>
        </geometry>
      </visual>
    </link>
    <joint name='wheel_right_joint' type='revolute'>
      <pose relative_to='base_footprint'>0.193 0 0.0607 0 1.57 0</pose>
      <parent>base_footprint</parent>
      <child>wheel_right_link</child>
      <axis>
        <xyz>0 0 1</xyz>
        <limit>
          <lower>-1e+16</lower>
          <upper>1e+16</upper>
        </limit>
        <dynamics>
          <spring_reference>0</spring_reference>
          <spring_stiffness>0</spring_stiffness>
        </dynamics>
      </axis>
    </joint>
    <link name='wheel_right_link'>
      <pose relative_to='wheel_right_joint'>0 0 0 0 -0 0</pose>
      <inertial>
        <pose>0 0 0 0 -0 0</pose>
        <mass>1</mass>
        <inertia>
          <ixx>0.001</ixx>
          <ixy>0</ixy>
          <ixz>0</ixz>
          <iyy>0.001</iyy>
          <iyz>0</iyz>
          <izz>0.001</izz>
        </inertia>
      </inertial>
      <collision name='wheel_right_link_collision'>
        <pose>0 0 0 0 -0 0</pose>
        <geometry>
          <mesh>
            <scale>1 1 1</scale>
            <uri>model://meshes/M_rodatrativa.dae</uri>
          </mesh>
        </geometry>
      </collision>
      <visual name='wheel_right_link_visual'>
        <pose>0 0 0 0 -0 0</pose>
        <geometry>
          <mesh>
            <scale>1 1 1</scale>
            <uri>model://meshes/M_rodatrativa.dae</uri>
          </mesh>
        </geometry>
      </visual>
    </link>
  </model>
</sdf>
